[2021-02-01 06:36:45,278] {taskinstance.py:670} INFO - Dependencies all met for <TaskInstance: comic_app_v2.send_notification 2021-01-30T00:00:00+00:00 [queued]>
[2021-02-01 06:36:45,296] {taskinstance.py:670} INFO - Dependencies all met for <TaskInstance: comic_app_v2.send_notification 2021-01-30T00:00:00+00:00 [queued]>
[2021-02-01 06:36:45,296] {taskinstance.py:880} INFO - 
--------------------------------------------------------------------------------
[2021-02-01 06:36:45,296] {taskinstance.py:881} INFO - Starting attempt 1 of 3
[2021-02-01 06:36:45,296] {taskinstance.py:882} INFO - 
--------------------------------------------------------------------------------
[2021-02-01 06:36:45,305] {taskinstance.py:901} INFO - Executing <Task(SlackAPIPostOperator): send_notification> on 2021-01-30T00:00:00+00:00
[2021-02-01 06:36:45,308] {standard_task_runner.py:54} INFO - Started process 306 to run task
[2021-02-01 06:36:45,338] {standard_task_runner.py:77} INFO - Running: ['airflow', 'run', 'comic_app_v2', 'send_notification', '2021-01-30T00:00:00+00:00', '--job_id', '19', '--pool', 'default_pool', '--raw', '-sd', 'DAGS_FOLDER/manga.py', '--cfg_path', '/tmp/tmpgb09o_ok']
[2021-02-01 06:36:45,339] {standard_task_runner.py:78} INFO - Job 19: Subtask send_notification
[2021-02-01 06:36:45,364] {logging_mixin.py:112} INFO - Running <TaskInstance: comic_app_v2.send_notification 2021-01-30T00:00:00+00:00 [running]> on host 5e1208a57967
[2021-02-01 06:36:45,904] {taskinstance.py:1150} ERROR - Slack API call failed (invalid_auth)
Traceback (most recent call last):
  File "/home/airflow/.local/lib/python3.6/site-packages/airflow/models/taskinstance.py", line 984, in _run_raw_task
    result = task_copy.execute(context=context)
  File "/home/airflow/.local/lib/python3.6/site-packages/airflow/operators/slack_operator.py", line 85, in execute
    slack.call(self.method, self.api_params)
  File "/home/airflow/.local/lib/python3.6/site-packages/airflow/hooks/slack_hook.py", line 62, in call
    raise AirflowException(msg)
airflow.exceptions.AirflowException: Slack API call failed (invalid_auth)
[2021-02-01 06:36:45,905] {taskinstance.py:1194} INFO - Marking task as UP_FOR_RETRY. dag_id=comic_app_v2, task_id=send_notification, execution_date=20210130T000000, start_date=20210201T063645, end_date=20210201T063645
[2021-02-01 06:36:50,273] {local_task_job.py:102} INFO - Task exited with return code 1
