[2021-02-02 05:03:37,764] {taskinstance.py:670} INFO - Dependencies all met for <TaskInstance: test_slack_0.0.1.send_slack 2020-12-17T10:00:00+00:00 [queued]>
[2021-02-02 05:03:37,777] {taskinstance.py:670} INFO - Dependencies all met for <TaskInstance: test_slack_0.0.1.send_slack 2020-12-17T10:00:00+00:00 [queued]>
[2021-02-02 05:03:37,777] {taskinstance.py:880} INFO - 
--------------------------------------------------------------------------------
[2021-02-02 05:03:37,777] {taskinstance.py:881} INFO - Starting attempt 1 of 1
[2021-02-02 05:03:37,777] {taskinstance.py:882} INFO - 
--------------------------------------------------------------------------------
[2021-02-02 05:03:37,786] {taskinstance.py:901} INFO - Executing <Task(SlackAPIPostOperator): send_slack> on 2020-12-17T10:00:00+00:00
[2021-02-02 05:03:37,788] {standard_task_runner.py:54} INFO - Started process 1177 to run task
[2021-02-02 05:03:37,819] {standard_task_runner.py:77} INFO - Running: ['airflow', 'run', 'test_slack_0.0.1', 'send_slack', '2020-12-17T10:00:00+00:00', '--job_id', '36', '--pool', 'default_pool', '--raw', '-sd', 'DAGS_FOLDER/slack_message.py', '--cfg_path', '/tmp/tmp7kyky10y']
[2021-02-02 05:03:37,820] {standard_task_runner.py:78} INFO - Job 36: Subtask send_slack
[2021-02-02 05:03:37,845] {logging_mixin.py:112} INFO - Running <TaskInstance: test_slack_0.0.1.send_slack 2020-12-17T10:00:00+00:00 [running]> on host 5e1208a57967
[2021-02-02 05:03:38,380] {taskinstance.py:1150} ERROR - Slack API call failed (invalid_auth)
Traceback (most recent call last):
  File "/home/airflow/.local/lib/python3.6/site-packages/airflow/models/taskinstance.py", line 984, in _run_raw_task
    result = task_copy.execute(context=context)
  File "/home/airflow/.local/lib/python3.6/site-packages/airflow/operators/slack_operator.py", line 85, in execute
    slack.call(self.method, self.api_params)
  File "/home/airflow/.local/lib/python3.6/site-packages/airflow/hooks/slack_hook.py", line 62, in call
    raise AirflowException(msg)
airflow.exceptions.AirflowException: Slack API call failed (invalid_auth)
[2021-02-02 05:03:38,381] {taskinstance.py:1194} INFO - Marking task as FAILED. dag_id=test_slack_0.0.1, task_id=send_slack, execution_date=20201217T100000, start_date=20210202T050337, end_date=20210202T050338
[2021-02-02 05:03:42,761] {local_task_job.py:102} INFO - Task exited with return code 1
[2021-02-02 05:04:51,907] {taskinstance.py:664} INFO - Dependencies not met for <TaskInstance: test_slack_0.0.1.send_slack 2020-12-17T10:00:00+00:00 [failed]>, dependency 'Task Instance State' FAILED: Task is in the 'failed' state which is not a valid state for execution. The task must be cleared in order to be run.
[2021-02-02 05:04:51,911] {local_task_job.py:90} INFO - Task is not able to be run
